<?xml version="1.0" ?>
<robot name = "camel_momentum_inverted_pendulum">
  
  <material name = "red">
    <color rgba = "0.914 0.263 0.212 0.7"/>
  </material>
  
  <material name = "stylish">
    <color rgba = "0.243 0.271 0.318 0.9"/>
  </material>
  
  <material name = "lime">
    <color rgba = "0.804 0.863 0.223 0.9"/>
  </material>
  
  <material name = "blue">
    <color rgba = "0.329 0.463 0.890 0.7 "/>
  </material>
  
  <link name = "world"/>
  <joint name = "fixed_world" type = "fixed">
    <parent link = "world"/>
    <child link = "base"/>
  </joint>
  
  <link name = "base">
    <visual>
      <origin rpy = "1.570796 0 0 " xyz = "0 0 0.01275"/>
      <geometry>
        <cylinder length = "0.02" radius = "0.005"/>
      </geometry>
      <material name = "stylish"/>
    </visual>
  </link>
  
  <joint name = "base-pitch" type = "continuous">
    <origin rpy = "0 0 0" xyz = "0 0 0.01275"/>
    <parent link = "base"/>
    <child link = "back-calf"/>
    <axis xyz = "0 1 0"/>
  </joint>
  
  <link name = "back-calf">
    <visual>
      <origin rpy = "0.0 0 0" xyz = "0 0 0.115"/>
      <geometry>
        <box size = "0.03 0.02 0.23"/>
      </geometry>
      <material name = "blue"/>
    </visual>
    
    <inertial>
      <origin rpy = "0.0 0 0" xyz = "0 0 0.115"/>
      <mass value = "0.207"/>
      <inertia ixx = "0.000922668" ixy = "0" ixz = "0" iyy = "0.000922668" iyx = "0" iyz = "0" izz = "2.0286e-05"
               izx = "0" izy = "0"/>
    </inertial>
    
    <collision>
      <origin rpy = "0.0 0 0" xyz = "0 0 0.115"/>
      <geometry>
        <box size = "0.003 0.002 0.2"/>
      </geometry>
    </collision>
  </link>
  
  <joint name = "back-knee-pitch" type = "revolute">
    <origin rpy = "0 0 0" xyz = "0 0 0.23"/>
    <parent link = "back-calf"/>
    <child link = "back-thigh"/>
    <axis xyz = "0 1 0"/>
  </joint>
  
  <link name = "back-thigh">
    <visual>
      <origin rpy = "0.0 0 0" xyz = "0 0 0.115"/>
      <geometry>
        <box size = "0.03 0.02 0.23"/>
      </geometry>
      <material name = "blue"/>
    </visual>
    
    <inertial>
      <origin rpy = "0.0 0 0" xyz = "0 0 0.115"/>
      <mass value = "1.229"/>
      <inertia ixx = "0.00624742" ixy = "0" ixz = "0" iyy = "0.00605702" iyx = "0" iyz = "0" izz = "0.00146876"
               izx = "0" izy = "0"/>
    </inertial>
  </link>
  
  <joint name = "back-hip-pitch" type = "revolute">
    <origin rpy = "0 0 0" xyz = "0.0 0.0 0.23"/>
    <parent link = "back-thigh"/>
    <child link = "body"/>
    <axis xyz = "0 1 0"/>
  </joint>
  
  <link name = "body">
    <visual>
      <origin rpy = "0 0 0" xyz = "0.241 0.0 0.0"/>
      <geometry>
        <box size = "0.482 0.122265 0.111"/>
      </geometry>
      <material name = "red"/>
    </visual>
    
    <inertial>
      <origin rpy = "0 0 0" xyz = "0.241 0.0 0.0"/>
      <mass value = "5.0075"/>
      <inertia ixx = "0.0113794" ixy = "0.0" ixz = "0.0" iyy = "0.102088" iyz = "0.0" izz = "0.103185"/>
    </inertial>
    
    <collision>
      <origin rpy = "0 0 0" xyz = "0.241 0.0 0.0"/>
      <geometry>
        <box size = "0.482 0.122265 0.111"/>
      </geometry>
      <material name = "red"/>
    </collision>
  
  </link>
  
  <joint name = "front-hip-pitch" type = "revolute">
    <origin rpy = "0 0 0" xyz = "0.482 0.0 0.0"/>
    <parent link = "body"/>
    <child link = "front-thigh"/>
    <axis xyz = "0 1 0"/>
  </joint>
  
  <link name = "front-thigh">
    <visual>
      <origin rpy = "0.0 0 0" xyz = "0 0 -0.115"/>
      <geometry>
        <box size = "0.03 0.02 0.23"/>
      </geometry>
      <material name = "blue"/>
    </visual>
    
    <inertial>
      <origin rpy = "0.0 0 0" xyz = "0 0 -0.115"/>
      <mass value = "1.229"/>
      <inertia ixx = "0.00624742" ixy = "0" ixz = "0" iyy = "0.00605702" iyx = "0" iyz = "0" izz = "0.00146876"
               izx = "0" izy = "0"/>
    </inertial>
  </link>
  
  <joint name = "front-knee-pitch" type = "revolute">
    <origin rpy = "0 0 0" xyz = "0.0 0.0 -0.23"/>
    <parent link = "front-thigh"/>
    <child link = "front-calf"/>
    <axis xyz = "0 1 0"/>
  </joint>
  
  <link name = "front-calf">
    <visual>
      <origin rpy = "0.0 0 0" xyz = "0 0 -0.115"/>
      <geometry>
        <box size = "0.03 0.02 0.23"/>
      </geometry>
      <material name = "blue"/>
    </visual>
    
    <inertial>
      <origin rpy = "0.0 0 0" xyz = "0 0 -0.115"/>
      <mass value = "0.207"/>
      <inertia ixx = "0.000922668" ixy = "0" ixz = "0" iyy = "0.000922668" iyx = "0" iyz = "0" izz = "2.0286e-05"
               izx = "0" izy = "0"/>
    </inertial>
  
    <collision>
      <origin rpy = "0.0 0 0" xyz = "0 0 -0.115"/>
      <geometry>
        <box size = "0.003 0.002 0.2"/>
      </geometry>
    </collision>

  </link>

</robot>